Workbook

Sheet Sheet1
A1: Financial Year | B1: Metric | C1: Type | D1: FY Value | E1: Prev FY Value | F1: YoY%
A2: 2019-2020 | B2: Movements | C2: International | D2: 431853 | E2: 452641 | F2: =IFERROR(ROUND((D2-E2)*100/E2,1)&"%","—")
A3: 2020-2021 | B3: Movements | C3: International | D3: 134824 | E3: 431853 | F3: =IFERROR(ROUND((D3-E3)*100/E3,1)&"%","—")
A4: 2021-2022 | B4: Movements | C4: International | D4: 211836 | E4: 134824 | F4: =IFERROR(ROUND((D4-E4)*100/E4,1)&"%","—")
A5: 2022-2023 | B5: Movements | C5: International | D5: 365048 | E5: 211836 | F5: =IFERROR(ROUND((D5-E5)*100/E5,1)&"%","—")
A6: 2023-2024 | B6: Movements | C6: International | D6: 425172 | E6: 365048 | F6: =IFERROR(ROUND((D6-E6)*100/E6,1)&"%","—")
A7: 2024-2025 | B7: Movements | C7: International | D7: 465119 | E7: 425172 | F7: =IFERROR(ROUND((D7-E7)*100/E7,1)&"%","—")
A8: 2025-2026 | B8: Movements | C8: International | D8: 481280 | E8: 465119 | F8: =IFERROR(ROUND((D8-E8)*100/E8,1)&"%","—")
A10: 2019-2020 | B10: Movements | C10: Domestic | D10: 2155201 | E10: 2153323 | F10: =IFERROR(ROUND((D10-E10)*100/E10,1)&"%","—")
A11: 2020-2021 | B11: Movements | C11: Domestic | D11: 1061916 | E11: 2155201 | F11: =IFERROR(ROUND((D11-E11)*100/E11,1)&"%","—")
A12: 2021-2022 | B12: Movements | C12: Domestic | D12: 1545276 | E12: 1061916 | F12: =IFERROR(ROUND((D12-E12)*100/E12,1)&"%","—")
A13: 2022-2023 | B13: Movements | C13: Domestic | D13: 2143267 | E13: 1545276 | F13: =IFERROR(ROUND((D13-E13)*100/E13,1)&"%","—")
A14: 2023-2024 | B14: Movements | C14: Domestic | D14: 2252421 | E14: 2143267 | F14: =IFERROR(ROUND((D14-E14)*100/E14,1)&"%","—")
... A43: 2020-2021 | B43: Freight | C43: Domestic | D43: 952487 | E43: 1325173 | F43: =IFERROR(ROUND((D43-E43)*100/E43,1)&"%","—")
A44: 2021-2022 | B44: Freight | C44: Domestic | D44: 1179690 | E44: 952487 | F44: =IFERROR(ROUND((D44-E44)*100/E44,1)&"%","—") | H44: Total CAGR= | I44: =ROUND(((D16/D10)^(1/6)-1)*100,2)&"%"
A45: 2022-2023 | B45: Freight | C45: Domestic | D45: 1294045 | E45: 1179690 | F45: =IFERROR(ROUND((D45-E45)*100/E45,1)&"%","—")
A46: 2023-2024 | B46: Freight | C46: Domestic | D46: 1320150 | E46: 1294045 | F46: =IFERROR(ROUND((D46-E46)*100/E46,1)&"%","—")
A47: 2024-2025 | B47: Freight | C47: Domestic | D47: 1394167 | E47: 1320150 | F47: =IFERROR(ROUND((D47-E47)*100/E47,1)&"%","—")
A48: 2025-2026 | B48: Freight | C48: Domestic | D48: 1512474 | E48: 1394167 | F48: =IFERROR(ROUND((D48-E48)*100/E48,1)&"%","—") | H48: Total CAGR= | I48: =ROUND(((D32/D26)^(1/6)-1)*100,2)&"%"
G51: Total international movements across all 7 years | H51: =D2+D3+D4+D5+D6+D7+D8 | I51: =ROUND(H51/(H51+H52)*100,5)&"%"
G52: Total domestic movements across all 7 years | H52: =D10+D11+D12+D13+D14+D15+D16
G53: Total movements across all 7 years | H53: =H51+H52
G54: Average movements in a year | H54: =ROUND(H53/7,0)
G55: Total international passengers across all 7 years | H55: =D18+D19+D20+D21+D22+D23+D24 | I55: =ROUND(H55/(H55+H56)*100,5)&"%"
G56: Total domestic passengers across all 7 years | H56: =D26+D27+D28+D29+D30+D31+D32 | I56: =ROUND(H56/(H55+H56)*100,5)&"%"
G57: Total passengers across all 7 years | H57: =H55+H56
G58: Average passengers in a year | H58: =ROUND(H57/7,0)
G59: Year with lowest movement,passengers | H59: FY 2020-2021
G60: Year with highest movement,passengers | H60: FY 2025-2026

Sheet Sheet2
A1: Financial Year | B1: Region | C1: Metric | D1: Value | E1: Share%
A2: 2019-2020 | B2: Eastern | C2: Movements | D2: =(Sheet1!D2+Sheet1!D10)*E2/100 | E2: 13
A3: 2020-2021 | B3: Eastern | C3: Movements | D3: =(Sheet1!D3+Sheet1!D11)*E3/100 | E3: 11.4
A4: 2021-2022 | B4: Eastern | C4: Movements | D4: =(Sheet1!D4+Sheet1!D12)*E4/100 | E4: 12
A5: 2022-2023 | B5: Eastern | C5: Movements | D5: =(Sheet1!D5+Sheet1!D13)*E5/100 | E5: 10.9
A6: 2023-2024 | B6: Eastern | C6: Movements | D6: =(Sheet1!D6+Sheet1!D14)*E6/100 | E6: 10.9
A7: 2024-2025 | B7: Eastern | C7: Movements | D7: =(Sheet1!D7+Sheet1!D15)*E7/100 | E7: 10.6
A8: 2025-2026 | B8: Eastern | C8: Movements | D8: =(Sheet1!D8+Sheet1!D16)*E8/100 | E8: 11.1
A10: 2019-2020 | B10: Eastern | C10: Passengers | D10: =(Sheet1!D18+Sheet1!D26)*E10/100 | E10: 13.4
A11: 2020-2021 | B11: Eastern | C11: Passengers | D11: =(Sheet1!D19+Sheet1!D27)*E11/100 | E11: 14.5
A12: 2021-2022 | B12: Eastern | C12: Passengers | D12: =(Sheet1!D20+Sheet1!D28)*E12/100 | E12: 12.3
A13: 2022-2023 | B13: Eastern | C13: Passengers | D13: =(Sheet1!D21+Sheet1!D29)*E13/100 | E13: 10.8
A14: 2023-2024 | B14: Eastern | C14: Passengers | D14: =(Sheet1!D22+Sheet1!D30)*E14/100 | E14: 10.4
A15: 2024-2025 | B15: Eastern | C15: Passengers | D15: =(Sheet1!D23+Sheet1!D31)*E15/100 | E15: 10.5
A16: 2025-2026 | B16: Eastern | C16: Passengers | D16: =(Sheet1!D24+Sheet1!D32)*E16/100 | E16: 10.9
A18: 2019-2020 | B18: North East | C18: Movements | D18: =(Sheet1!D2+Sheet1!D10)*E18/100 | E18: 3.6
A19: 2020-2021 | B19: North East | C19: Movements | D19: =(Sheet1!D3+Sheet1!D11)*E19/100 | E19: 3.8
A20: 2021-2022 | B20: North East | C20: Movements | D20: =(Sheet1!D4+Sheet1!D12)*E20/100 | E20: 4.1
A21: 2022-2023 | B21: North East | C21: Movements | D21: =(Sheet1!D5+Sheet1!D13)*E21/100 | E21: 3.7
A22: 2023-2024 | B22: North East | C22: Movements | D22: =(Sheet1!D6+Sheet1!D14)*E22/100 | E22: 3.9
A23: 2024-2025 | B23: North East | C23: Movements | D23: =(Sheet1!D7+Sheet1!D15)*E23/100 | E23: 3.6
A24: 2025-2026 | B24: North East | C24: Movements | D24: =(Sheet1!D8+Sheet1!D16)*E24/100 | E24: 3.2
A26: 2019-2020 | B26: North East | C26: Passengers | D26: =(Sheet1!D18+Sheet1!D26)*E26/100 | E26: 3.4
A27: 2020-2021 | B27: North East | C27: Passengers | D27: =(Sheet1!D19+Sheet1!D27)*E27/100 | E27: 3.6
A28: 2021-2022 | B28: North East | C28: Passengers | D28: =(Sheet1!D20+Sheet1!D28)*E28/100 | E28: 3.2
A29: 2022-2023 | B29: North East | C29: Passengers | D29: =(Sheet1!D21+Sheet1!D29)*E29/100 | E29: 3
A30: 2023-2024 | B30: North East | C30: Passengers | D30: =(Sheet1!D22+Sheet1!D30)*E30/100 | E30: 3
A31: 2024-2025 | B31: North East | C31: Passengers | D31: =(Sheet1!D23+Sheet1!D31)*E31/100 | E31: 3
A32: 2025-2026 | B32: North East | C32: Passengers | D32: =(Sheet1!D24+Sheet1!D32)*E32/100 | E32: 3
A34: 2019-2020 | B34: North | C34: Movements | D34: =(Sheet1!D2+Sheet1!D10)*E34/100 | E34: 27
A35: 2020-2021 | B35: North | C35: Movements | D35: =(Sheet1!D3+Sheet1!D11)*E35/100 | E35: 25.6
A36: 2021-2022 | B36: North | C36: Movements | D36: =(Sheet1!D4+Sheet1!D12)*E36/100 | E36: 30.3
A37: 2022-2023 | B37: North | C37: Movements | D37: =(Sheet1!D5+Sheet1!D13)*E37/100 | E37: 27.2
A38: 2023-2024 | B38: North | C38: Movements | D38: =(Sheet1!D6+Sheet1!D14)*E38/100 | E38: 27
A39: 2024-2025 | B39: North | C39: Movements | D39: =(Sheet1!D7+Sheet1!D15)*E39/100 | E39: 27.2
A40: 2025-2026 | B40: North | C40: Movements | D40: =(Sheet1!D8+Sheet1!D16)*E40/100 | E40: 26.9
A42: 2019-2020 | B42: North | C42: Passengers | D42: =(Sheet1!D18+Sheet1!D26)*E42/100 | E42: 29.7
A43: 2020-2021 | B43: North | C43: Passengers | D43: =(Sheet1!D19+Sheet1!D27)*E43/100 | E43: 22.1
A44: 2021-2022 | B44: North | C44: Passengers | D44: =(Sheet1!D20+Sheet1!D28)*E44/100 | E44: 32.3
A45: 2022-2023 | B45: North | C45: Passengers | D45: =(Sheet1!D21+Sheet1!D29)*E45/100 | E45: 29.9
...

Sheet FY19-20_Annex3
A1: ANNEXURE III-C: Total Passengers (Intl + Domestic) | 2019-2020
A2: Source: DGCA Annexure-III | April to March 2019-2020
A3: S.No | B3: Airport | C3: FY Current (Total) | D3: FY Intl | E3: FY Domestic | F3: FY Prev (Total) | G3: FY Change% | H3: Airport Category
A4: INTERNATIONAL AIRPORTS
A5: 1 | B5: Chennai | C5: 22266722 | D5: 835987 | E5: 21430735 | F5: 22543822 | G5: =IFERROR(ROUND((C5-F5)*100/F5,1)&"%","—") | H5: International
A6: 2 | B6: Kolkata | C6: 22015391 | D6: 2939322 | E6: 19076069 | F6: 21877350 | G6: =IFERROR(ROUND((C6-F6)*100/F6,1)&"%","—") | H6: International
A7: 3 | B7: Ahmedabad | C7: 11432996 | D7: 2321304 | E7: 9111692 | F7: 11172468 | G7: =IFERROR(ROUND((C7-F7)*100/F7,1)&"%","—") | H7: International
A8: 4 | B8: Goa | C8: 8356240 | D8: 704878 | E8: 7651362 | F8: 8467326 | G8: =IFERROR(ROUND((C8-F8)*100/F8,1)&"%","—") | H8: International
A9: 5 | B9: Guwahati | C9: 5457449 | D9: 35160 | E9: 5422289 | F9: 5745628 | G9: =IFERROR(ROUND((C9-F9)*100/F9,1)&"%","—") | H9: International
A10: 6 | B10: Lucknow | C10: 5433757 | D10: 737088 | E10: 4696669 | F10: 5532819 | G10: =IFERROR(ROUND((C10-F10)*100/F10,1)&"%","—") | H10: International
A11: 7 | B11: Jaipur | C11: 5031561 | D11: 528992 | E11: 4502569 | F11: 5471223 | G11: =IFERROR(ROUND((C11-F11)*100/F11,1)&"%","—") | H11: International
A12: 8 | B12: Trivandrum | C12: 3919193 | D12: 2209964 | E12: 1709229 | F12: 4434459 | G12: =IFERROR(ROUND((C12-F12)*100/F12,1)&"%","—") | H12: International
A13: 9 | B13: Bhubaneswar | C13: 3672246 | D13: 70887 | E13: 3601359 | F13: 4158731 | G13: =IFERROR(ROUND((C13-F13)*100/F13,1)&"%","—") | H13: International
A14: 10 | B14: Calicut | C14: 3229910 | D14: 2700556 | E14: 529354 | F14: 3360847 | G14: =IFERROR(ROUND((C14-F14)*100/F14,1)&"%","—") | H14: International
A15: 11 | B15: Coimbatore | C15: 2842835 | D15: 238232 | E15: 2604603 | F15: 3000882 | G15: =IFERROR(ROUND((C15-F15)*100/F15,1)&"%","—") | H15: International
A16: 12 | B16: Varanasi | C16: 3010702 | D16: 231730 | E16: 2778972 | F16: 2785015 | G16: =IFERROR(ROUND((C16-F16)*100/F16,1)&"%","—") | H16: International
... A24: 20 | B24: Tirupati | C24: 834984 | D24: 23 | E24: 834961 | F24: 834652 | G24: =IFERROR(ROUND((C24-F24)*100/F24,1)&"%","—") | H24: International
B25: TOTAL INTL | C25: 110346415 | D25: 12251318 | E25: 98095097 | F25: 112639968 | G25: =IFERROR(ROUND((C25-F25)*100/F25,1)&"%","—")
A26: JV INTERNATIONAL AIRPORTS
A27: 1 | B27: Delhi (DIAL) | C27: 67301016 | D27: 17831081 | E27: 49469935 | F27: 69233864 | G27: =IFERROR(ROUND((C27-F27)*100/F27,1)&"%","—") | H27: JV International
A28: 2 | B28: Mumbai (MIAL) | C28: 45873329 | D28: 12355552 | E28: 33517777 | F28: 48815063 | G28: =IFERROR(ROUND((C28-F28)*100/F28,1)&"%","—") | H28: JV International
A29: 3 | B29: Bengaluru (BIAL) | C29: 32361666 | D29: 4578531 | E29: 27783135 | F29: 33307702 | G29: =IFERROR(ROUND((C29-F29)*100/F29,1)&"%","—") | H29: JV International
A30: 4 | B30: Hyderabad (GHIAL) | C30: 21651878 | D30: 3919874 | E30: 17732004 | F30: 21403972 | G30: =IFERROR(ROUND((C30-F30)*100/F30,1)&"%","—") | H30: JV International
A31: 5 | B31: Kochi (CIAL) | C31: 9624334 | D31: 4676314 | E31: 4948020 | F31: 10119825 | G31: =IFERROR(ROUND((C31-F31)*100/F31,1)&"%","—") | H31: JV International
A32: 6 | B32: Nagpur | C32: 3061548 | D32: 115175 | E32: 2946373 | F32: 2801910 | G32: =IFERROR(ROUND((C32-F32)*100/F32,1)&"%","—") | H32: JV International
A33: 7 | B33: Kannur (KIAL) | C33: 1583600 | D33: 805940 | E33: 777660 | F33: 224302 | G33: =IFERROR(ROUND((C33-F33)*100/F33,1)&"%","—") | H33: JV International
B34: TOTAL JV | C34: 181457371 | D34: 44282467 | E34: 137174904 | F34: 185906638 | G34: =IFERROR(ROUND((C34-F34)*100/F34,1)&"%","—")
A35: CUSTOM AIRPORTS
A36: 1 | B36: Pune | C36: 8085607 | D36: 158125 | E36: 7927482 | F36: 9070927 | G36: =IFERROR(ROUND((C36-F36)*100/F36,1)&"%","—") | H36: Custom
A37: 2 | B37: Patna | C37: 4525765 | D37: 0 | E37: 4525765 | F37: 4061990 | G37: =IFERROR(ROUND((C37-F37)*100/F37,1)&"%","—") | H37: Custom
A38: 3 | B38: Bagdogra | C38: 3216640 | D38: 19472 | E38: 3197168 | F38: 2898784 | G38: =IFERROR(ROUND((C38-F38)*100/F38,1)&"%","—") | H38: Custom
A39: 4 | B39: Visakhapatnam | C39: 2681283 | D39: 143535 | E39: 2537748 | F39: 2853390 | G39: =IFERROR(ROUND((C39-F39)*100/F39,1)&"%","—") | H39: Custom
A40: 5 | B40: Chandigarh | C40: 2445202 | D40: 121495 | E40: 2323707 | F40: 2097698 | G40: =IFERROR(ROUND((C40-F40)*100/F40,1)&"%","—") | H40: Custom
A41: 6 | B41: Madurai | C41: 1422337 | D41: 349816 | E41: 1072521 | F41: 1520016 | G41: =IFERROR(ROUND((C41-F41)*100/F41,1)&"%","—") | H41: Custom
A42: 7 | B42: Surat | C42: 1515557 | D42: 44151 | E42: 1471406 | F42: 1238724 | G42: =IFERROR(ROUND((C42-F42)*100/F42,1)&"%","—") | H42: Custom
A43: 8 | B43: Aurangabad | C43: 347734 | D43: 2116 | E43: 345618 | F43: 347781 | G43: =IFERROR(ROUND((C43-F43)*100/F43,1)&"%","—") | H43: Custom
A44: 9 | B44: Gaya | C44: 237452 | D44: 139952 | E44: 97500 | F44: 213635 | G44: =IFERROR(ROUND((C44-F44)*100/F44,1)&"%","—") | H44: Custom
A45: 10 | B45: Indore | C45: 2918971 | D45: 25522 | E45: 2893449 | F45: 3158938 | G45: =IFERROR(ROUND((C45-F45)*100/F45,1)&"%","—") | H45: Custom
B46: TOTAL CUSTOM | C46: 27396548 | D46: 1004184 | E46: 26392364 | F46: 27461883 | G46: =IFERROR(ROUND((C46-F46)*100/F46,1)&"%","—")
B47: GRAND TOTAL | C47: 341050651 | D47: 66543642 | E47: 274507009 | F47: 344699733 | G47: =IFERROR(ROUND((C47-F47)*100/F47,1)&"%","—")

Sheet FY20-21_Annex3
A1: ANNEXURE III-C: Total Passengers (Intl + Domestic) | 2020-2021
A2: Source: DGCA Annexure-III | April to March 2020-2021
A3: S.No | B3: Airport | C3: FY Current (Total) | D3: FY Intl | E3: FY Domestic | F3: FY Prev (Total) | G3: FY Change% | H3: Airport Category
A4: INTERNATIONAL AIRPORTS
A5: 1 | B5: Chennai | C5: 5495707 | D5: 591571 | E5: 4904136 | F5: 22266722 | G5: =IFERROR(ROUND((C5-F5)*100/F5,1)&"%","—") | H5: International
A6: 2 | B6: Kolkata | C6: 7728906 | D6: 143081 | E6: 7585825 | F6: 22015391 | G6: =IFERROR(ROUND((C6-F6)*100/F6,1)&"%","—") | H6: International
A7: 3 | B7: Ahmedabad | C7: 3642413 | D7: 204491 | E7: 3437922 | F7: 11432996 | G7: =IFERROR(ROUND((C7-F7)*100/F7,1)&"%","—") | H7: International
A8: 4 | B8: Goa | C8: 2890545 | D8: 39866 | E8: 2850679 | F8: 8356240 | G8: =IFERROR(ROUND((C8-F8)*100/F8,1)&"%","—") | H8: International
A9: 5 | B9: Guwahati | C9: 2189135 | D9: 368 | E9: 2188767 | F9: 5457449 | G9: =IFERROR(ROUND((C9-F9)*100/F9,1)&"%","—") | H9: International
A10: 6 | B10: Lucknow | C10: 2441037 | D10: 414429 | E10: 2026608 | F10: 5433757 | G10: =IFERROR(ROUND((C10-F10)*100/F10,1)&"%","—") | H10: International
A11: 7 | B11: Jaipur | C11: 1850187 | D11: 130250 | E11: 1719937 | F11: 5031561 | G11: =IFERROR(ROUND((C11-F11)*100/F11,1)&"%","—") | H11: International
A12: 8 | B12: Trivandrum | C12: 935435 | D12: 458876 | E12: 476559 | F12: 3919193 | G12: =IFERROR(ROUND((C12-F12)*100/F12,1)&"%","—") | H12: International
A13: 9 | B13: Bhubaneswar | C13: 1571933 | D13: 6277 | E13: 1565656 | F13: 3672246 | G13: =IFERROR(ROUND((C13-F13)*100/F13,1)&"%","—") | H13: International
A14: 10 | B14: Calicut | C14: 902012 | D14: 712872 | E14: 189140 | F14: 3229910 | G14: =IFERROR(ROUND((C14-F14)*100/F14,1)&"%","—") | H14: International
A15: 11 | B15: Coimbatore | C15: 846649 | D15: 26495 | E15: 820154 | F15: 2842835 | G15: =IFERROR(ROUND((C15-F15)*100/F15,1)&"%","—") | H15: International
A16: 12 | B16: Varanasi | C16: 1466718 | D16: 18563 | E16: 1448155 | F16: 3010702 | G16: =IFERROR(ROUND((C16-F16)*100/F16,1)&"%","—") | H16: International
... A24: 20 | B24: Tirupati | C24: 352375 | D24: 0 | E24: 352375 | F24: 834984 | G24: =IFERROR(ROUND((C24-F24)*100/F24,1)&"%","—") | H24: International
B25: TOTAL INTL | C25: 37341384 | D25: 3359361 | E25: 33982023 | F25: 110346415 | G25: =IFERROR(ROUND((C25-F25)*100/F25,1)&"%","—")
A26: JV INTERNATIONAL AIRPORTS
A27: 1 | B27: Delhi (DIAL) | C27: 22583736 | D27: 3207233 | E27: 19376503 | F27: 67301016 | G27: =IFERROR(ROUND((C27-F27)*100/F27,1)&"%","—") | H27: JV International
A28: 2 | B28: Mumbai (MIAL) | C28: 11054811 | D28: 1218512 | E28: 9836299 | F28: 45873329 | G28: =IFERROR(ROUND((C28-F28)*100/F28,1)&"%","—") | H28: JV International
A29: 3 | B29: Bengaluru (BIAL) | C29: 10914194 | D29: 465386 | E29: 10448808 | F29: 32361666 | G29: =IFERROR(ROUND((C29-F29)*100/F29,1)&"%","—") | H29: JV International
A30: 4 | B30: Hyderabad (GHIAL) | C30: 8048248 | D30: 575329 | E30: 7472919 | F30: 21651878 | G30: =IFERROR(ROUND((C30-F30)*100/F30,1)&"%","—") | H30: JV International
A31: 5 | B31: Kochi (CIAL) | C31: 2458458 | D31: 909551 | E31: 1548907 | F31: 9624334 | G31: =IFERROR(ROUND((C31-F31)*100/F31,1)&"%","—") | H31: JV International
A32: 6 | B32: Nagpur | C32: 948237 | D32: 371 | E32: 947866 | F32: 3061548 | G32: =IFERROR(ROUND((C32-F32)*100/F32,1)&"%","—") | H32: JV International
A33: 7 | B33: Kannur (KIAL) | C33: 481084 | D33: 296094 | E33: 184990 | F33: 1583600 | G33: =IFERROR(ROUND((C33-F33)*100/F33,1)&"%","—") | H33: JV International
B34: TOTAL JV | C34: 56488768 | D34: 6672476 | E34: 49816292 | F34: 181457371 | G34: =IFERROR(ROUND((C34-F34)*100/F34,1)&"%","—")
A35: CUSTOM AIRPORTS
A36: 1 | B36: Pune | C36: 2137859 | D36: 4878 | E36: 2132981 | F36: 8085607 | G36: =IFERROR(ROUND((C36-F36)*100/F36,1)&"%","—") | H36: Custom
A37: 2 | B37: Patna | C37: 2710000 | D37: 0 | E37: 2710000 | F37: 4525765 | G37: =IFERROR(ROUND((C37-F37)*100/F37,1)&"%","—") | H37: Custom
A38: 3 | B38: Bagdogra | C38: 1473310 | D38: 678 | E38: 1472632 | F38: 3216640 | G38: =IFERROR(ROUND((C38-F38)*100/F38,1)&"%","—") | H38: Custom
A39: 4 | B39: Indore | C39: 896304 | D39: 913 | E39: 895391 | F39: 2918971 | G39: =IFERROR(ROUND((C39-F39)*100/F39,1)&"%","—") | H39: Custom
A40: 5 | B40: Visakhapatnam | C40: 1113513 | D40: 7581 | E40: 1105932 | F40: 2681283 | G40: =IFERROR(ROUND((C40-F40)*100/F40,1)&"%","—") | H40: Custom
A41: 6 | B41: Chandigarh | C41: 1381634 | D41: 11245 | E41: 1370389 | F41: 2445202 | G41: =IFERROR(ROUND((C41-F41)*100/F41,1)&"%","—") | H41: Custom
A42: 7 | B42: Surat | C42: 564260 | D42: 0 | E42: 564260 | F42: 1515557 | G42: =IFERROR(ROUND((C42-F42)*100/F42,1)&"%","—") | H42: Custom
A43: 8 | B43: Madurai | C43: 565539 | D43: 58056 | E43: 507483 | F43: 1422337 | G43: =IFERROR(ROUND((C43-F43)*100/F43,1)&"%","—") | H43: Custom
A44: 9 | B44: Aurangabad | C44: 145561 | D44: 0 | E44: 145561 | F44: 347734 | G44: =IFERROR(ROUND((C44-F44)*100/F44,1)&"%","—") | H44: Custom
A45: 10 | B45: Gaya | C45: 69655 | D45: 13083 | E45: 56572 | F45: 237452 | G45: =IFERROR(ROUND((C45-F45)*100/F45,1)&"%","—") | H45: Custom
B46: TOTAL CUSTOM | C46: 11057635 | D46: 96434 | E46: 10961201 | F46: 27396548 | G46: =IFERROR(ROUND((C46-F46)*100/F46,1)&"%","—")
B47: GRAND TOTAL | C47: 115379783 | D47: 10128283 | E47: 105251500 | F47: 341050651 | G47: =IFERROR(ROUND((C47-F47)*100/F47,1)&"%","—")

Sheet FY21-22_Annex3
A1: ANNEXURE III-C: Total Passengers (Intl + Domestic) | 2021-2022
A2: Source: DGCA Annexure-III | April to March 2021-2022
A3: S.No | B3: Airport | C3: FY Current (Total) | D3: FY Intl | E3: FY Domestic | F3: FY Prev (Total) | G3: FY Change% | H3: Airport Category
A4: INTERNATIONAL AIRPORTS
A5: 1 | B5: Kolkata | C5: 11036108 | D5: 342665 | E5: 10693443 | F5: 7728906 | G5: =IFERROR(ROUND((C5-F5)*100/F5,1)&"%","—") | H5: International
A6: 2 | B6: Chennai | C6: 9533301 | D6: 1674644 | E6: 7858657 | F6: 5495707 | G6: =IFERROR(ROUND((C6-F6)*100/F6,1)&"%","—") | H6: International
A7: 3 | B7: Goa | C7: 5238051 | D7: 104200 | E7: 5133851 | F7: 2890545 | G7: =IFERROR(ROUND((C7-F7)*100/F7,1)&"%","—") | H7: International
A8: 4 | B8: Srinagar | C8: 3158400 | D8: 8678 | E8: 3149722 | F8: 1802904 | G8: =IFERROR(ROUND((C8-F8)*100/F8,1)&"%","—") | H8: International
A9: 5 | B9: Bhubaneswar | C9: 2135893 | D9: 16 | E9: 2135877 | F9: 1571933 | G9: =IFERROR(ROUND((C9-F9)*100/F9,1)&"%","—") | H9: International
A10: 6 | B10: Varanasi | C10: 1708220 | D10: 55138 | E10: 1653082 | F10: 1466718 | G10: =IFERROR(ROUND((C10-F10)*100/F10,1)&"%","—") | H10: International
A11: 7 | B11: Calicut | C11: 1665145 | D11: 1355424 | E11: 309721 | F11: 902012 | G11: =IFERROR(ROUND((C11-F11)*100/F11,1)&"%","—") | H11: International
A12: 8 | B12: Amritsar | C12: 1382004 | D12: 341121 | E12: 1040883 | F12: 854352 | G12: =IFERROR(ROUND((C12-F12)*100/F12,1)&"%","—") | H12: International
A13: 9 | B13: Coimbatore | C13: 1285922 | D13: 65382 | E13: 1220540 | F13: 846649 | G13: =IFERROR(ROUND((C13-F13)*100/F13,1)&"%","—") | H13: International
A14: 10 | B14: Vijayawada | C14: 625131 | D14: 46020 | E14: 579111 | F14: 507215 | G14: =IFERROR(ROUND((C14-F14)*100/F14,1)&"%","—") | H14: International
A15: 11 | B15: Imphal | C15: 814913 | D15: 0 | E15: 814913 | F15: 492752 | G15: =IFERROR(ROUND((C15-F15)*100/F15,1)&"%","—") | H15: International
A16: 12 | B16: Port Blair | C16: 761610 | D16: 0 | E16: 761610 | F16: 400361 | G16: =IFERROR(ROUND((C16-F16)*100/F16,1)&"%","—") | H16: International
... A19: 15 | B19: Kushinagar | C19: 11155 | D19: 257 | E19: 10898 | F19: 0 | G19: =IFERROR(ROUND((C19-F19)*100/F19,1)&"%","—") | H19: International
B20: TOTAL INTL | C20: 40535901 | D20: 4401002 | E20: 36134899 | F20: 25668332 | G20: =IFERROR(ROUND((C20-F20)*100/F20,1)&"%","—")
A21: PPP INTERNATIONAL
A22: 1 | B22: Ahmedabad | C22: 5670896 | D22: 625423 | E22: 5045473 | F22: 3642413 | G22: =IFERROR(ROUND((C22-F22)*100/F22,1)&"%","—") | H22: PPP International
A23: 2 | B23: Lucknow | C23: 3303960 | D23: 592722 | E23: 2711238 | F23: 2441037 | G23: =IFERROR(ROUND((C23-F23)*100/F23,1)&"%","—") | H23: PPP International
A24: 3 | B24: Mangaluru | C24: 1013453 | D24: 243801 | E24: 769652 | F24: 614845 | G24: =IFERROR(ROUND((C24-F24)*100/F24,1)&"%","—") | H24: PPP International
A25: 4 | B25: Guwahati | C25: 3148956 | D25: 16 | E25: 3148940 | F25: 2189135 | G25: =IFERROR(ROUND((C25-F25)*100/F25,1)&"%","—") | H25: PPP International
A26: 5 | B26: Jaipur | C26: 2943171 | D26: 175004 | E26: 2768167 | F26: 1850187 | G26: =IFERROR(ROUND((C26-F26)*100/F26,1)&"%","—") | H26: PPP International
A27: 6 | B27: Trivandrum | C27: 1655506 | D27: 956059 | E27: 699447 | F27: 935435 | G27: =IFERROR(ROUND((C27-F27)*100/F27,1)&"%","—") | H27: PPP International
B28: TOTAL PPP | C28: 17735942 | D28: 2593025 | E28: 15142917 | F28: 11673052 | G28: =IFERROR(ROUND((C28-F28)*100/F28,1)&"%","—")
A29: JV INTERNATIONAL AIRPORTS
A30: 1 | B30: Delhi (DIAL) | C30: 39339998 | D30: 6521605 | E30: 32818393 | F30: 22583736 | G30: =IFERROR(ROUND((C30-F30)*100/F30,1)&"%","—") | H30: JV International
A31: 2 | B31: Mumbai (MIAL) | C31: 21747892 | D31: 3182990 | E31: 18564902 | F31: 11054811 | G31: =IFERROR(ROUND((C31-F31)*100/F31,1)&"%","—") | H31: JV International
A32: 3 | B32: Bengaluru (BIAL) | C32: 16287097 | D32: 1101152 | E32: 15185945 | F32: 10914194 | G32: =IFERROR(ROUND((C32-F32)*100/F32,1)&"%","—") | H32: JV International
A33: 4 | B33: Hyderabad (GHIAL) | C33: 12429796 | D33: 1430140 | E33: 10999656 | F33: 8048248 | G33: =IFERROR(ROUND((C33-F33)*100/F33,1)&"%","—") | H33: JV International
A34: 5 | B34: Kochi (CIAL) | C34: 4717777 | D34: 2201982 | E34: 2515795 | F34: 2458458 | G34: =IFERROR(ROUND((C34-F34)*100/F34,1)&"%","—") | H34: JV International
A35: 6 | B35: Nagpur | C35: 1605433 | D35: 11267 | E35: 1594166 | F35: 948237 | G35: =IFERROR(ROUND((C35-F35)*100/F35,1)&"%","—") | H35: JV International
A36: 7 | B36: Kannur (KIAL) | C36: 799122 | D36: 522630 | E36: 276492 | F36: 481084 | G36: =IFERROR(ROUND((C36-F36)*100/F36,1)&"%","—") | H36: JV International
B37: TOTAL JV | C37: 96927115 | D37: 14971766 | E37: 81955349 | F37: 56488768 | G37: =IFERROR(ROUND((C37-F37)*100/F37,1)&"%","—")
A38: ST GOVT/PVT INTERNATIONAL
A39: 1 | B39: Shirdi | C39: 176787 | D39: 0 | E39: 176787 | F39: 85673 | G39: =IFERROR(ROUND((C39-F39)*100/F39,1)&"%","—") | H39: St Govt/Pvt Intl
B40: TOTAL ST GOVT/PVT | C40: 176787 | D40: 0 | E40: 176787 | F40: 85673 | G40: =IFERROR(ROUND((C40-F40)*100/F40,1)&"%","—")
A41: CUSTOM AIRPORTS
A42: 1 | B42: Pune | C42: 3713491 | D42: 18455 | E42: 3695036 | F42: 2137859 | G42: =IFERROR(ROUND((C42-F42)*100/F42,1)&"%","—") | H42: Custom
...

Sheet FY22-23_Annex3
A1: ANNEXURE III-C: Total Passengers (Intl + Domestic) | 2022-2023
A2: Source: DGCA Annexure-III | April to March 2022-2023
A3: S.No | B3: Airport | C3: FY Current (Total) | D3: FY Intl | E3: FY Domestic | F3: FY Prev (Total) | G3: FY Change% | H3: Airport Category
A4: INTERNATIONAL AIRPORTS
A5: 1 | B5: Kolkata | C5: 17768862 | D5: 1965919 | E5: 15802943 | F5: 11036108 | G5: =IFERROR(ROUND((C5-F5)*100/F5,1)&"%","—") | H5: International
A6: 2 | B6: Chennai | C6: 18571393 | D6: 4862634 | E6: 13708759 | F6: 9533301 | G6: =IFERROR(ROUND((C6-F6)*100/F6,1)&"%","—") | H6: International
A7: 3 | B7: Goa | C7: 8359393 | D7: 467410 | E7: 7891983 | F7: 5238051 | G7: =IFERROR(ROUND((C7-F7)*100/F7,1)&"%","—") | H7: International
A8: 4 | B8: Srinagar | C8: 4409665 | D8: 11591 | E8: 4398074 | F8: 3158400 | G8: =IFERROR(ROUND((C8-F8)*100/F8,1)&"%","—") | H8: International
A9: 5 | B9: Bhubaneswar | C9: 3624905 | D9: 36 | E9: 3624869 | F9: 2135893 | G9: =IFERROR(ROUND((C9-F9)*100/F9,1)&"%","—") | H9: International
A10: 6 | B10: Varanasi | C10: 2521442 | D10: 109419 | E10: 2412023 | F10: 1708220 | G10: =IFERROR(ROUND((C10-F10)*100/F10,1)&"%","—") | H10: International
A11: 7 | B11: Calicut | C11: 2982879 | D11: 2405011 | E11: 577868 | F11: 1665145 | G11: =IFERROR(ROUND((C11-F11)*100/F11,1)&"%","—") | H11: International
A12: 8 | B12: Amritsar | C12: 2516518 | D12: 755134 | E12: 1761384 | F12: 1382004 | G12: =IFERROR(ROUND((C12-F12)*100/F12,1)&"%","—") | H12: International
A13: 9 | B13: Coimbatore | C13: 2557263 | D13: 194817 | E13: 2362446 | F13: 1285922 | G13: =IFERROR(ROUND((C13-F13)*100/F13,1)&"%","—") | H13: International
A14: 10 | B14: Imphal | C14: 1233997 | D14: 0 | E14: 1233997 | F14: 814913 | G14: =IFERROR(ROUND((C14-F14)*100/F14,1)&"%","—") | H14: International
A15: 11 | B15: Port Blair | C15: 1273138 | D15: 0 | E15: 1273138 | F15: 761610 | G15: =IFERROR(ROUND((C15-F15)*100/F15,1)&"%","—") | H15: International
A16: 12 | B16: Vijayawada | C16: 966383 | D16: 36618 | E16: 929765 | F16: 625131 | G16: =IFERROR(ROUND((C16-F16)*100/F16,1)&"%","—") | H16: International
... A19: 15 | B19: Kushinagar | C19: 23221 | D19: 0 | E19: 23221 | F19: 11155 | G19: =IFERROR(ROUND((C19-F19)*100/F19,1)&"%","—") | H19: International
B20: TOTAL INTL | C20: 69242586 | D20: 11942622 | E20: 57299964 | F20: 40535901 | G20: =IFERROR(ROUND((C20-F20)*100/F20,1)&"%","—")
A21: PPP INTERNATIONAL
A22: 1 | B22: Ahmedabad | C22: 10137001 | D22: 1539374 | E22: 8597627 | F22: 5670896 | G22: =IFERROR(ROUND((C22-F22)*100/F22,1)&"%","—") | H22: PPP International
A23: 2 | B23: Lucknow | C23: 5220528 | D23: 872531 | E23: 4347997 | F23: 3303960 | G23: =IFERROR(ROUND((C23-F23)*100/F23,1)&"%","—") | H23: PPP International
A24: 3 | B24: Guwahati | C24: 5051480 | D24: 12165 | E24: 5039315 | F24: 3148956 | G24: =IFERROR(ROUND((C24-F24)*100/F24,1)&"%","—") | H24: PPP International
A25: 4 | B25: Jaipur | C25: 4764382 | D25: 405388 | E25: 4358994 | F25: 2943171 | G25: =IFERROR(ROUND((C25-F25)*100/F25,1)&"%","—") | H25: PPP International
A26: 5 | B26: Trivandrum | C26: 3478067 | D26: 1798682 | E26: 1679385 | F26: 1655506 | G26: =IFERROR(ROUND((C26-F26)*100/F26,1)&"%","—") | H26: PPP International
A27: 6 | B27: Mangaluru | C27: 1809266 | D27: 531792 | E27: 1277474 | F27: 1013453 | G27: =IFERROR(ROUND((C27-F27)*100/F27,1)&"%","—") | H27: PPP International
B28: TOTAL PPP | C28: 30460724 | D28: 5159932 | E28: 25300792 | F28: 17735942 | G28: =IFERROR(ROUND((C28-F28)*100/F28,1)&"%","—")
A29: JV INTERNATIONAL AIRPORTS
A30: 1 | B30: Delhi (DIAL) | C30: 65327833 | D30: 15652343 | E30: 49675490 | F30: 39339998 | G30: =IFERROR(ROUND((C30-F30)*100/F30,1)&"%","—") | H30: JV International
A31: 2 | B31: Mumbai (MIAL) | C31: 43930298 | D31: 11207221 | E31: 32723077 | F31: 21747892 | G31: =IFERROR(ROUND((C31-F31)*100/F31,1)&"%","—") | H31: JV International
A32: 3 | B32: Bengaluru (BIAL) | C32: 31911429 | D32: 3785264 | E32: 28126165 | F32: 16287097 | G32: =IFERROR(ROUND((C32-F32)*100/F32,1)&"%","—") | H32: JV International
A33: 4 | B33: Hyderabad (GHIAL) | C33: 20996027 | D33: 3420785 | E33: 17575242 | F33: 12429796 | G33: =IFERROR(ROUND((C33-F33)*100/F33,1)&"%","—") | H33: JV International
A34: 5 | B34: Kochi (CIAL) | C34: 8812531 | D34: 4174768 | E34: 4637763 | F34: 4717777 | G34: =IFERROR(ROUND((C34-F34)*100/F34,1)&"%","—") | H34: JV International
A35: 6 | B35: Nagpur | C35: 2565155 | D35: 65512 | E35: 2499643 | F35: 1605433 | G35: =IFERROR(ROUND((C35-F35)*100/F35,1)&"%","—") | H35: JV International
A36: 7 | B36: Kannur (KIAL) | C36: 1257086 | D36: 853091 | E36: 403995 | F36: 799122 | G36: =IFERROR(ROUND((C36-F36)*100/F36,1)&"%","—") | H36: JV International
B37: TOTAL JV | C37: 174800359 | D37: 39158984 | E37: 135641375 | F37: 96927115 | G37: =IFERROR(ROUND((C37-F37)*100/F37,1)&"%","—")
A38: ST GOVT/PVT INTERNATIONAL
A39: 1 | B39: Shirdi | C39: 733038 | D39: 0 | E39: 733038 | F39: 176787 | G39: =IFERROR(ROUND((C39-F39)*100/F39,1)&"%","—") | H39: St Govt/Pvt Intl
A40: 2 | B40: Goa (MOPA) | C40: 664160 | D40: 0 | E40: 664160 | F40: 0 | G40: =IFERROR(ROUND((C40-F40)*100/F40,1)&"%","—") | H40: St Govt/Pvt Intl
B41: TOTAL ST GOVT/PVT | C41: 1397198 | D41: 0 | E41: 1397198 | F41: 176787 | G41: =IFERROR(ROUND((C41-F41)*100/F41,1)&"%","—")
A42: CUSTOM AIRPORTS
...

Sheet FY23-24_Annex3
A1: ANNEXURE III-C: Total Passengers (Intl + Domestic) | 2023-2024
A2: Source: DGCA Annexure-III | April to March 2023-2024
A3: S.No | B3: Airport | C3: FY Current (Total) | D3: FY Intl | E3: FY Domestic | F3: FY Prev (Total) | G3: FY Change% | H3: Airport Category
A4: INTERNATIONAL AIRPORTS
A5: 1 | B5: Chennai | C5: 21207262 | D5: 5879078 | E5: 15328184 | F5: 18571393 | G5: =IFERROR(ROUND((C5-F5)*100/F5,1)&"%","—") | H5: International
A6: 2 | B6: Kolkata | C6: 19784417 | D6: 2468601 | E6: 17315816 | F6: 17768862 | G6: =IFERROR(ROUND((C6-F6)*100/F6,1)&"%","—") | H6: International
A7: 3 | B7: Goa | C7: 6872411 | D7: 427089 | E7: 6445322 | F7: 8359393 | G7: =IFERROR(ROUND((C7-F7)*100/F7,1)&"%","—") | H7: International
A8: 4 | B8: Srinagar | C8: 4205541 | D8: 23711 | E8: 4181830 | F8: 4409665 | G8: =IFERROR(ROUND((C8-F8)*100/F8,1)&"%","—") | H8: International
A9: 5 | B9: Bhubaneswar | C9: 4600615 | D9: 89919 | E9: 4510696 | F9: 3624905 | G9: =IFERROR(ROUND((C9-F9)*100/F9,1)&"%","—") | H9: International
A10: 6 | B10: Calicut | C10: 3320250 | D10: 2676932 | E10: 643318 | F10: 2982879 | G10: =IFERROR(ROUND((C10-F10)*100/F10,1)&"%","—") | H10: International
A11: 7 | B11: Coimbatore | C11: 2904611 | D11: 211087 | E11: 2693524 | F11: 2557263 | G11: =IFERROR(ROUND((C11-F11)*100/F11,1)&"%","—") | H11: International
A12: 8 | B12: Varanasi | C12: 2996698 | D12: 116704 | E12: 2879994 | F12: 2521442 | G12: =IFERROR(ROUND((C12-F12)*100/F12,1)&"%","—") | H12: International
A13: 9 | B13: Amritsar | C13: 3085598 | D13: 981405 | E13: 2104193 | F13: 2516518 | G13: =IFERROR(ROUND((C13-F13)*100/F13,1)&"%","—") | H13: International
A14: 10 | B14: Trichy | C14: 1763942 | D14: 1305186 | E14: 458756 | F14: 1514260 | G14: =IFERROR(ROUND((C14-F14)*100/F14,1)&"%","—") | H14: International
A15: 11 | B15: Port Blair | C15: 1453811 | D15: 0 | E15: 1453811 | F15: 1273138 | G15: =IFERROR(ROUND((C15-F15)*100/F15,1)&"%","—") | H15: International
A16: 12 | B16: Imphal | C16: 1274666 | D16: 0 | E16: 1274666 | F16: 1233997 | G16: =IFERROR(ROUND((C16-F16)*100/F16,1)&"%","—") | H16: International
... A19: 15 | B19: Kushinagar | C19: 17742 | D19: 0 | E19: 17742 | F19: 23221 | G19: =IFERROR(ROUND((C19-F19)*100/F19,1)&"%","—") | H19: International
B20: TOTAL INTL | C20: 75420732 | D20: 14216484 | E20: 61204248 | F20: 69242586 | G20: =IFERROR(ROUND((C20-F20)*100/F20,1)&"%","—")
A21: PPP INTERNATIONAL
A22: 1 | B22: Ahmedabad | C22: 11696227 | D22: 1977965 | E22: 9718262 | F22: 10137001 | G22: =IFERROR(ROUND((C22-F22)*100/F22,1)&"%","—") | H22: PPP International
A23: 2 | B23: Lucknow | C23: 6184850 | D23: 976061 | E23: 5208789 | F23: 5220528 | G23: =IFERROR(ROUND((C23-F23)*100/F23,1)&"%","—") | H23: PPP International
A24: 3 | B24: Guwahati | C24: 5957609 | D24: 30321 | E24: 5927288 | F24: 5051480 | G24: =IFERROR(ROUND((C24-F24)*100/F24,1)&"%","—") | H24: PPP International
A25: 4 | B25: Jaipur | C25: 5466552 | D25: 413871 | E25: 5052681 | F25: 4764382 | G25: =IFERROR(ROUND((C25-F25)*100/F25,1)&"%","—") | H25: PPP International
A26: 5 | B26: Trivandrum | C26: 4405318 | D26: 2050218 | E26: 2355100 | F26: 3478067 | G26: =IFERROR(ROUND((C26-F26)*100/F26,1)&"%","—") | H26: PPP International
A27: 6 | B27: Mangaluru | C27: 2030387 | D27: 520498 | E27: 1509889 | F27: 1809266 | G27: =IFERROR(ROUND((C27-F27)*100/F27,1)&"%","—") | H27: PPP International
B28: TOTAL PPP | C28: 35740943 | D28: 5968934 | E28: 29772009 | F28: 30460724 | G28: =IFERROR(ROUND((C28-F28)*100/F28,1)&"%","—")
A29: JV INTERNATIONAL AIRPORTS
A30: 1 | B30: Delhi (DIAL) | C30: 73673708 | D30: 19470161 | E30: 54203547 | F30: 65327833 | G30: =IFERROR(ROUND((C30-F30)*100/F30,1)&"%","—") | H30: JV International
A31: 2 | B31: Mumbai (MIAL) | C31: 52820754 | D31: 14318743 | E31: 38502011 | F31: 43930298 | G31: =IFERROR(ROUND((C31-F31)*100/F31,1)&"%","—") | H31: JV International
A32: 3 | B32: Bengaluru (BIAL) | C32: 37528533 | D32: 4667631 | E32: 32860902 | F32: 31911429 | G32: =IFERROR(ROUND((C32-F32)*100/F32,1)&"%","—") | H32: JV International
A33: 4 | B33: Hyderabad (GHIAL) | C33: 25042282 | D33: 4214573 | E33: 20827709 | F33: 20996027 | G33: =IFERROR(ROUND((C33-F33)*100/F33,1)&"%","—") | H33: JV International
A34: 5 | B34: Kochi (CIAL) | C34: 10365655 | D34: 4920194 | E34: 5445461 | F34: 8812531 | G34: =IFERROR(ROUND((C34-F34)*100/F34,1)&"%","—") | H34: JV International
A35: 6 | B35: Nagpur | C35: 2794427 | D35: 110730 | E35: 2683697 | F35: 2565155 | G35: =IFERROR(ROUND((C35-F35)*100/F35,1)&"%","—") | H35: JV International
A36: 7 | B36: Kannur (KIAL) | C36: 1177891 | D36: 764537 | E36: 413354 | F36: 1257086 | G36: =IFERROR(ROUND((C36-F36)*100/F36,1)&"%","—") | H36: JV International
B37: TOTAL JV | C37: 203403250 | D37: 48466569 | E37: 154936681 | F37: 174800359 | G37: =IFERROR(ROUND((C37-F37)*100/F37,1)&"%","—")
A38: ST GOVT/PVT INTERNATIONAL
A39: 1 | B39: Shirdi | C39: 724980 | D39: 20 | E39: 724960 | F39: 733038 | G39: =IFERROR(ROUND((C39-F39)*100/F39,1)&"%","—") | H39: St Govt/Pvt Intl
A40: 2 | B40: Goa (MOPA) | C40: 4406087 | D40: 115288 | E40: 4290799 | F40: 664160 | G40: =IFERROR(ROUND((C40-F40)*100/F40,1)&"%","—") | H40: St Govt/Pvt Intl
B41: TOTAL ST GOVT/PVT | C41: 5131067 | D41: 115308 | E41: 5015759 | F41: 1397198 | G41: =IFERROR(ROUND((C41-F41)*100/F41,1)&"%","—")
A42: CUSTOM AIRPORTS
...

Sheet FY24-25_Annex3
A1: ANNEXURE III-C: Total Passengers (Intl + Domestic) | 2024-2025
A2: Source: DGCA Annexure-III | April to March 2024-2025
A3: S.No | B3: Airport | C3: FY Current (Total) | D3: FY Intl | E3: FY Domestic | F3: FY Prev (Total) | G3: FY Change% | H3: Airport Category
A4: INTERNATIONAL AIRPORTS
A5: 1 | B5: Amritsar | C5: 3542880 | D5: 1153461 | E5: 2389419 | F5: 3085598 | G5: =IFERROR(ROUND((C5-F5)*100/F5,1)&"%","—") | H5: International
A6: 2 | B6: Ayodhya | C6: 1115016 | D6: 22 | E6: 1114994 | F6: 213015 | G6: =IFERROR(ROUND((C6-F6)*100/F6,1)&"%","—") | H6: International
A7: 3 | B7: Bhubaneswar | C7: 4838751 | D7: 124591 | E7: 4714160 | F7: 4600615 | G7: =IFERROR(ROUND((C7-F7)*100/F7,1)&"%","—") | H7: International
A8: 4 | B8: Chennai | C8: 22411290 | D8: 5855344 | E8: 16555946 | F8: 21207262 | G8: =IFERROR(ROUND((C8-F8)*100/F8,1)&"%","—") | H8: International
A9: 5 | B9: Coimbatore | C9: 3253190 | D9: 263385 | E9: 2989805 | F9: 2904611 | G9: =IFERROR(ROUND((C9-F9)*100/F9,1)&"%","—") | H9: International
A10: 6 | B10: Goa | C10: 7260779 | D10: 241752 | E10: 7019027 | F10: 6872411 | G10: =IFERROR(ROUND((C10-F10)*100/F10,1)&"%","—") | H10: International
A11: 7 | B11: Imphal | C11: 1406227 | D11: 2 | E11: 1406225 | F11: 1274666 | G11: =IFERROR(ROUND((C11-F11)*100/F11,1)&"%","—") | H11: International
A12: 8 | B12: Kolkata | C12: 21831118 | D12: 2419466 | E12: 19411652 | F12: 19784417 | G12: =IFERROR(ROUND((C12-F12)*100/F12,1)&"%","—") | H12: International
A13: 9 | B13: Kozhikode | C13: 3695944 | D13: 2965957 | E13: 729987 | F13: 3320250 | G13: =IFERROR(ROUND((C13-F13)*100/F13,1)&"%","—") | H13: International
A14: 10 | B14: Port Blair | C14: 1656704 | D14: 9929 | E14: 1646775 | F14: 1453811 | G14: =IFERROR(ROUND((C14-F14)*100/F14,1)&"%","—") | H14: International
A15: 11 | B15: Rajkot (Hirasar) | C15: 1088570 | D15: 0 | E15: 1088570 | F15: 525668 | G15: =IFERROR(ROUND((C15-F15)*100/F15,1)&"%","—") | H15: International
A16: 12 | B16: Srinagar | C16: 4472449 | D16: 13598 | E16: 4458851 | F16: 4205541 | G16: =IFERROR(ROUND((C16-F16)*100/F16,1)&"%","—") | H16: International
... A21: 17 | B21: Vijayawada | C21: 1388943 | D21: 28894 | E21: 1360049 | F21: 1062506 | G21: =IFERROR(ROUND((C21-F21)*100/F21,1)&"%","—") | H21: International
B22: TOTAL INTL | C22: 86651348 | D22: 14755012 | E22: 71896336 | F22: 77540167 | G22: =IFERROR(ROUND((C22-F22)*100/F22,1)&"%","—")
A23: PPP INTERNATIONAL
A24: 1 | B24: Ahmedabad | C24: 13427697 | D24: 2232203 | E24: 11195494 | F24: 11696227 | G24: =IFERROR(ROUND((C24-F24)*100/F24,1)&"%","—") | H24: PPP International
A25: 2 | B25: Guwahati | C25: 6160157 | D25: 58302 | E25: 6101855 | F25: 5957609 | G25: =IFERROR(ROUND((C25-F25)*100/F25,1)&"%","—") | H25: PPP International
A26: 3 | B26: Jaipur | C26: 6057249 | D26: 526542 | E26: 5530707 | F26: 5466552 | G26: =IFERROR(ROUND((C26-F26)*100/F26,1)&"%","—") | H26: PPP International
A27: 4 | B27: Lucknow | C27: 6438506 | D27: 1176551 | E27: 5261955 | F27: 6184850 | G27: =IFERROR(ROUND((C27-F27)*100/F27,1)&"%","—") | H27: PPP International
A28: 5 | B28: Mangaluru | C28: 2343032 | D28: 615039 | E28: 1727993 | F28: 2030387 | G28: =IFERROR(ROUND((C28-F28)*100/F28,1)&"%","—") | H28: PPP International
A29: 6 | B29: Thiruvananthapuram | C29: 4891009 | D29: 2344298 | E29: 2546711 | F29: 4405318 | G29: =IFERROR(ROUND((C29-F29)*100/F29,1)&"%","—") | H29: PPP International
B30: TOTAL PPP | C30: 39317650 | D30: 6952935 | E30: 32364715 | F30: 35740943 | G30: =IFERROR(ROUND((C30-F30)*100/F30,1)&"%","—")
A31: JV INTERNATIONAL AIRPORTS
A32: 1 | B32: Bengaluru (BIAL) | C32: 41875620 | D32: 5834155 | E32: 36041465 | F32: 37528533 | G32: =IFERROR(ROUND((C32-F32)*100/F32,1)&"%","—") | H32: JV International
A33: 2 | B33: Delhi (IGIA) | C33: 79259890 | D33: 21561977 | E33: 57697913 | F33: 73673708 | G33: =IFERROR(ROUND((C33-F33)*100/F33,1)&"%","—") | H33: JV International
A34: 3 | B34: Hyderabad (GHIAL) | C34: 29165232 | D34: 4731033 | E34: 24434199 | F34: 25042282 | G34: =IFERROR(ROUND((C34-F34)*100/F34,1)&"%","—") | H34: JV International
A35: 4 | B35: Kannur (KIAL) | C35: 1344021 | D35: 964073 | E35: 379948 | F35: 1177891 | G35: =IFERROR(ROUND((C35-F35)*100/F35,1)&"%","—") | H35: JV International
A36: 5 | B36: Kochi | C36: 11140778 | D36: 5242146 | E36: 5898632 | F36: 10365655 | G36: =IFERROR(ROUND((C36-F36)*100/F36,1)&"%","—") | H36: JV International
A37: 6 | B37: Mumbai (MIAL) | C37: 55122422 | D37: 15598554 | E37: 39523868 | F37: 52820754 | G37: =IFERROR(ROUND((C37-F37)*100/F37,1)&"%","—") | H37: JV International
A38: 7 | B38: Nagpur | C38: 2894099 | D38: 104448 | E38: 2789651 | F38: 2794427 | G38: =IFERROR(ROUND((C38-F38)*100/F38,1)&"%","—") | H38: JV International
B39: TOTAL JV | C39: 220802062 | D39: 54036386 | E39: 166765676 | F39: 203403250 | G39: =IFERROR(ROUND((C39-F39)*100/F39,1)&"%","—")
A40: ST GOVT/PVT INTERNATIONAL
A41: 1 | B41: Goa (MOPA) | C41: 4643852 | D41: 339854 | E41: 4303998 | F41: 4406087 | G41: =IFERROR(ROUND((C41-F41)*100/F41,1)&"%","—") | H41: St Govt/Pvt Intl
A42: 2 | B42: Shirdi | C42: 741540 | D42: 20 | E42: 741520 | F42: 724980 | G42: =IFERROR(ROUND((C42-F42)*100/F42,1)&"%","—") | H42: St Govt/Pvt Intl
B43: TOTAL ST GOVT/PVT | C43: 5385392 | D43: 339874 | E43: 5045518 | F43: 5131067 | G43: =IFERROR(ROUND((C43-F43)*100/F43,1)&"%","—")
A44: CUSTOM AIRPORTS
...

Sheet FY25-26_Annex3
A1: ANNEXURE III-C: Total Passengers (Intl + Domestic) | 2025-2026
A2: Source: DGCA Annexure-III | April to March 2025-2026
A3: S.No | B3: Airport | C3: FY Current (Total) | D3: FY Intl | E3: FY Domestic | F3: FY Prev (Total) | G3: FY Change% | H3: Airport Category
A4: INTERNATIONAL AIRPORTS
A5: 1 | B5: Amritsar | C5: 2941017 | D5: 997408 | E5: 1943609 | F5: 3542880 | G5: =IFERROR(ROUND((C5-F5)*100/F5,1)&"%","—") | H5: International
A6: 2 | B6: Ayodhya | C6: 923651 | D6: 0 | E6: 923651 | F6: 1115016 | G6: =IFERROR(ROUND((C6-F6)*100/F6,1)&"%","—") | H6: International
A7: 3 | B7: Bhubaneswar | C7: 5130834 | D7: 153473 | E7: 4977361 | F7: 4838751 | G7: =IFERROR(ROUND((C7-F7)*100/F7,1)&"%","—") | H7: International
A8: 4 | B8: Chennai | C8: 23017324 | D8: 6142731 | E8: 16874593 | F8: 22411290 | G8: =IFERROR(ROUND((C8-F8)*100/F8,1)&"%","—") | H8: International
A9: 5 | B9: Coimbatore | C9: 3420745 | D9: 297760 | E9: 3122985 | F9: 3253190 | G9: =IFERROR(ROUND((C9-F9)*100/F9,1)&"%","—") | H9: International
A10: 6 | B10: Goa | C10: 6126944 | D10: 186198 | E10: 5940746 | F10: 7244874 | G10: =IFERROR(ROUND((C10-F10)*100/F10,1)&"%","—") | H10: International
A11: 7 | B11: Imphal | C11: 1366765 | D11: 0 | E11: 1366765 | F11: 1406227 | G11: =IFERROR(ROUND((C11-F11)*100/F11,1)&"%","—") | H11: International
A12: 8 | B12: Kolkata | C12: 21102741 | D12: 2298213 | E12: 18804528 | F12: 21831118 | G12: =IFERROR(ROUND((C12-F12)*100/F12,1)&"%","—") | H12: International
A13: 9 | B13: Kozhikode | C13: 3855618 | D13: 2920143 | E13: 935475 | F13: 3695944 | G13: =IFERROR(ROUND((C13-F13)*100/F13,1)&"%","—") | H13: International
A14: 10 | B14: Port Blair | C14: 1816485 | D14: 1031 | E14: 1815454 | F14: 1656704 | G14: =IFERROR(ROUND((C14-F14)*100/F14,1)&"%","—") | H14: International
A15: 11 | B15: Rajkot (Hirasar) | C15: 1246996 | D15: 0 | E15: 1246996 | F15: 1088570 | G15: =IFERROR(ROUND((C15-F15)*100/F15,1)&"%","—") | H15: International
A16: 12 | B16: Srinagar | C16: 3372163 | D16: 5128 | E16: 3367035 | F16: 4472449 | G16: =IFERROR(ROUND((C16-F16)*100/F16,1)&"%","—") | H16: International
... A21: 17 | B21: Vijayawada | C21: 1411958 | D21: 40950 | E21: 1371008 | F21: 1388943 | G21: =IFERROR(ROUND((C21-F21)*100/F21,1)&"%","—") | H21: International
B22: TOTAL INTL | C22: 85308380 | D22: 14785967 | E22: 70522413 | F22: 86651348 | G22: =IFERROR(ROUND((C22-F22)*100/F22,1)&"%","—")
A23: PPP INTERNATIONAL
A24: 1 | B24: Ahmedabad | C24: 13822287 | D24: 2416259 | E24: 11406028 | F24: 13427697 | G24: =IFERROR(ROUND((C24-F24)*100/F24,1)&"%","—") | H24: PPP International
A25: 2 | B25: Guwahati | C25: 6622784 | D25: 75249 | E25: 6547535 | F25: 6160157 | G25: =IFERROR(ROUND((C25-F25)*100/F25,1)&"%","—") | H25: PPP International
A26: 3 | B26: Jaipur | C26: 5627147 | D26: 574923 | E26: 5052224 | F26: 6057249 | G26: =IFERROR(ROUND((C26-F26)*100/F26,1)&"%","—") | H26: PPP International
A27: 4 | B27: Lucknow | C27: 6065957 | D27: 1152003 | E27: 4913954 | F27: 6438506 | G27: =IFERROR(ROUND((C27-F27)*100/F27,1)&"%","—") | H27: PPP International
A28: 5 | B28: Mangaluru | C28: 2548088 | D28: 771426 | E28: 1776662 | F28: 2343032 | G28: =IFERROR(ROUND((C28-F28)*100/F28,1)&"%","—") | H28: PPP International
A29: 6 | B29: Thiruvananthapuram | C29: 4694206 | D29: 2490985 | E29: 2203221 | F29: 4891009 | G29: =IFERROR(ROUND((C29-F29)*100/F29,1)&"%","—") | H29: PPP International
B30: TOTAL PPP | C30: 39380469 | D30: 7480845 | E30: 31899624 | F30: 39317650 | G30: =IFERROR(ROUND((C30-F30)*100/F30,1)&"%","—")
A31: JV INTERNATIONAL AIRPORTS
A32: 1 | B32: Bengaluru (BIAL) | C32: 44470035 | D32: 7227399 | E32: 37242636 | F32: 41875620 | G32: =IFERROR(ROUND((C32-F32)*100/F32,1)&"%","—") | H32: JV International
A33: 2 | B33: Delhi (IGIA) | C33: 78701971 | D33: 21549460 | E33: 57152511 | F33: 79259890 | G33: =IFERROR(ROUND((C33-F33)*100/F33,1)&"%","—") | H33: JV International
A34: 3 | B34: Hyderabad (GHIAL) | C34: 30483885 | D34: 5463102 | E34: 25020783 | F34: 29165232 | G34: =IFERROR(ROUND((C34-F34)*100/F34,1)&"%","—") | H34: JV International
A35: 4 | B35: Kannur (KIAL) | C35: 1434168 | D35: 973391 | E35: 460777 | F35: 1344021 | G35: =IFERROR(ROUND((C35-F35)*100/F35,1)&"%","—") | H35: JV International
A36: 5 | B36: Kochi | C36: 11302552 | D36: 5330796 | E36: 5971756 | F36: 11140778 | G36: =IFERROR(ROUND((C36-F36)*100/F36,1)&"%","—") | H36: JV International
A37: 6 | B37: Mumbai (MIAL) | C37: 55290095 | D37: 16347263 | E37: 38942832 | F37: 55122422 | G37: =IFERROR(ROUND((C37-F37)*100/F37,1)&"%","—") | H37: JV International
A38: 7 | B38: Nagpur | C38: 3007734 | D38: 96174 | E38: 2911560 | F38: 2894099 | G38: =IFERROR(ROUND((C38-F38)*100/F38,1)&"%","—") | H38: JV International
B39: TOTAL JV | C39: 224690440 | D39: 56987585 | E39: 167702855 | F39: 220802062 | G39: =IFERROR(ROUND((C39-F39)*100/F39,1)&"%","—")
A40: ST GOVT/PVT INTERNATIONAL
A41: 1 | B41: Goa (MOPA) | C41: 5376516 | D41: 389497 | E41: 4987019 | F41: 4643852 | G41: =IFERROR(ROUND((C41-F41)*100/F41,1)&"%","—") | H41: St Govt/Pvt Intl
A42: 2 | B42: Navi Mumbai (NMIAL) | C42: 638394 | D42: 0 | E42: 638394 | F42: 0 | G42: =IFERROR(ROUND((C42-F42)*100/F42,1)&"%","—") | H42: St Govt/Pvt Intl
A43: 3 | B43: Shirdi | C43: 605913 | D43: 61 | E43: 605852 | F43: 741540 | G43: =IFERROR(ROUND((C43-F43)*100/F43,1)&"%","—") | H43: St Govt/Pvt Intl
B44: TOTAL ST GOVT/PVT | C44: 6620823 | D44: 389558 | E44: 6231265 | F44: 5385392 | G44: =IFERROR(ROUND((C44-F44)*100/F44,1)&"%","—")
...
